<robot xmlns:xacro="http://www.ros.org/wiki/xacro" name="dummybot">
    
    <xacro:include filename="$(find dummybot_description )/urdf/dummybot.gazebo"/>


    <link name="base_link">
        <inertial>
            <origin xyz="0.0 0.0 0.0" rpy="0.0 0.0 0.0"/>
            <mass value="1.0"/>
            <inertia ixx="0.1" ixy="0.0" ixz="0.0" iyy="0.1" iyz="0.0" izz="0.1"/>
        </inertial>
        <visual name="">
            <origin xyz="0.0 0.0 0.0" rpy="0.0 0.0 0.0"/>
            <geometry>
                <box size="0.4 0.2 0.1"/>
            </geometry>
            <material name="">
                <color rgba="0.1 0.0 0.5 1.0"/>
                <texture filename=""/>
            </material>
        </visual>
        <collision>
            <origin xyz="0.0 0.0 0.0" rpy="0.0 0.0 0.0"/>
            <geometry>
                <box size="0.4 0.2 0.1"/>
            </geometry>
        </collision>
    </link>

        
    <joint name="left_wheel_joint" type="continuous">
        <origin xyz="0.0 0.15 0.0" rpy="0.0 1.5705 1.5705"/>
        <parent link="base_link"/>
        <child link="left_wheel"/>
        <axis xyz="0.0 0.0 1.0"/>
    </joint>    

        
    <joint name="right_wheel_joint" type="continuous">
        <origin xyz="0.0 -0.15 0.0" rpy="0.0 1.5705 1.5705"/>
        <parent link="base_link"/>
        <child link="right_wheel"/>
        <axis xyz="0.0 0.0 1.0"/>
    </joint>  

    <link name="front_caster_wheel">
        <inertial>
            <origin xyz="0.0 0.0 0.0" rpy="0.0 0.0 0.0"/>
            <mass value="1.0"/>
            <inertia ixx="0.1" ixy="0.0" ixz="0.0" iyy="0.1" iyz="0.0" izz="0.1"/>
        </inertial>
        <visual name="">
            <origin xyz="0.0 0.0 0.0" rpy="0.0 0.0 0.0"/>
            <geometry>
                <sphere radius="0.0499"/>
            </geometry>
            <material name="">
                <color rgba="0.1 0.1 0.1 1.0"/>
                <texture filename=""/>
            </material>
        </visual>
        <collision>
            <origin xyz="0.0 0.0 0.0" rpy="0.0 0.0 0.0"/>
            <geometry>
            <sphere radius="0.0499"/>
            </geometry>
        </collision>
    </link>
        
    <joint name="front_caster_wheel_joint" type="fixed">
        <origin xyz="0.15 0.0 -0.05" rpy="0.0 1.5705 1.5705"/>
        <parent link="base_link"/>
        <child link="front_caster_wheel"/>
        <axis xyz="0.0 0.0 0.0"/>
    </joint>  

    <link name="back_caster_wheel">
        <inertial>
            <origin xyz="0.0 0.0 0.0" rpy="0.0 0.0 0.0"/>
            <mass value="1.0"/>
            <inertia ixx="0.1" ixy="0.0" ixz="0.0" iyy="0.1" iyz="0.0" izz="0.1"/>
        </inertial>
        <visual name="">
            <origin xyz="0.0 0.0 0.0" rpy="0.0 0.0 0.0"/>
            <geometry>
                <sphere radius="0.0499"/>
            </geometry>
            <material name="">
                <color rgba="0.1 0.1 0.1 1.0"/>
                <texture filename=""/>
            </material>
        </visual>
        <collision>
            <origin xyz="0.0 0.0 0.0" rpy="0.0 0.0 0.0"/>
            <geometry>
            <sphere radius="0.0499"/>
            </geometry>
        </collision>
    </link>
        
    <joint name="back_caster_wheel_joint" type="fixed">
        <origin xyz="-0.15 0.0 -0.05" rpy="0.0 1.5705 1.5705"/>
        <parent link="base_link"/>
        <child link="back_caster_wheel"/>
        <axis xyz="0.0 0.0 0.0"/>
    </joint>  


</robot>