<robot xmlns:xacro="http://www.ros.org/wiki/xacro" name="dummybot">
    
    <xacro:include filename="$(find dummybot_description )/urdf/dummybot.gazebo"/>
    <xacro:include filename="$(find dummybot_description )/urdf/wheels.xacro"/>


    <link name="base_link">
        <inertial>
            <origin xyz="0.0 0.0 0.0" rpy="0.0 0.0 0.0"/>
            <mass value="1.0"/>
            <inertia ixx="0.1" ixy="0.0" ixz="0.0" iyy="0.1" iyz="0.0" izz="0.1"/>
        </inertial>
        <visual name="">
            <origin xyz="0.0 0.0 0.0" rpy="0.0 0.0 0.0"/>
            <geometry>
                <box size="0.4 0.2 0.1"/>
            </geometry>
            <material name="">
                <color rgba="0.1 0.0 0.5 1.0"/>
                <texture filename=""/>
            </material>
        </visual>
        <collision>
            <origin xyz="0.0 0.0 0.0" rpy="0.0 0.0 0.0"/>
            <geometry>
                <box size="0.4 0.2 0.1"/>
            </geometry>
        </collision>
    </link>

        
    <joint name="left_wheel_joint" type="continuous">
        <origin xyz="0.0 0.15 0.0" rpy="0.0 1.5705 1.5705"/>
        <parent link="base_link"/>
        <child link="left_wheel"/>
        <axis xyz="0.0 0.0 1.0"/>
    </joint>    

        
    <joint name="right_wheel_joint" type="continuous">
        <origin xyz="0.0 -0.15 0.0" rpy="0.0 1.5705 1.5705"/>
        <parent link="base_link"/>
        <child link="right_wheel"/>
        <axis xyz="0.0 0.0 1.0"/>
    </joint>  

    <link name="front_caster_wheel">
        <inertial>
            <origin xyz="0.0 0.0 0.0" rpy="0.0 0.0 0.0"/>
            <mass value="1.0"/>
            <inertia ixx="0.1" ixy="0.0" ixz="0.0" iyy="0.1" iyz="0.0" izz="0.1"/>
        </inertial>
        <visual name="">
            <origin xyz="0.0 0.0 0.0" rpy="0.0 0.0 0.0"/>
            <geometry>
                <sphere radius="0.0499"/>
            </geometry>
            <material name="">
                <color rgba="0.1 0.1 0.1 1.0"/>
                <texture filename=""/>
            </material>
        </visual>
        <collision>
            <origin xyz="0.0 0.0 0.0" rpy="0.0 0.0 0.0"/>
            <geometry>
            <sphere radius="0.0499"/>
            </geometry>
        </collision>
    </link>
        
    <joint name="front_caster_wheel_joint" type="fixed">
        <origin xyz="0.15 0.0 -0.05" rpy="0.0 1.5705 1.5705"/>
        <parent link="base_link"/>
        <child link="front_caster_wheel"/>
        <axis xyz="0.0 0.0 0.0"/>
    </joint>  

    <link name="back_caster_wheel">
        <inertial>
            <origin xyz="0.0 0.0 0.0" rpy="0.0 0.0 0.0"/>
            <mass value="1.0"/>
            <inertia ixx="0.1" ixy="0.0" ixz="0.0" iyy="0.1" iyz="0.0" izz="0.1"/>
        </inertial>
        <visual name="">
            <origin xyz="0.0 0.0 0.0" rpy="0.0 0.0 0.0"/>
            <geometry>
                <sphere radius="0.0499"/>
            </geometry>
            <material name="">
                <color rgba="0.1 0.1 0.1 1.0"/>
                <texture filename=""/>
            </material>
        </visual>
        <collision>
            <origin xyz="0.0 0.0 0.0" rpy="0.0 0.0 0.0"/>
            <geometry>
            <sphere radius="0.0499"/>
            </geometry>
        </collision>
    </link>
        
    <joint name="back_caster_wheel_joint" type="fixed">
        <origin xyz="-0.15 0.0 -0.05" rpy="0.0 1.5705 1.5705"/>
        <parent link="base_link"/>
        <child link="back_caster_wheel"/>
        <axis xyz="0.0 0.0 0.0"/>
    </joint>  
    
    <link name="lidar_link">
        <visual>
            <origin xyz="0 0 0" rpy="0 0 0"/>
            <geometry>
                <cylinder radius="0.05" length="0.09"/>
            </geometry>
            <material name="lidar_material">
                <color rgba="0 0 0 1"/>
            </material>
        </visual>
        <collision>
            <origin xyz="0 0 0" rpy="0 0 0"/>
            <geometry>
                <cylinder radius="0.05" length="0.09"/>
            </geometry>
        </collision>
        <inertial>
            <origin xyz="0 0 0" rpy="0 0 0"/>
            <mass value="1"/>
            <inertia ixx="0.3333333333333333" ixy="0" ixz="0" iyy="0.5" iyz="0" izz="0.3333333333333333"/>
        </inertial>
    </link>

        <!-- Lidar Joint -->
    <joint name="lidar_joint" type="fixed">
        <parent link="base_link"/>
        <child link="lidar_link"/>
        <origin xyz="0 0 0.09" rpy="0 0 0"/>
    </joint>

    <!-- Camera Link -->
    <link name="camera_link">
        <visual>
            <origin xyz="0 0 0" rpy="0 0 0"/>
            <geometry>
                <box size="0.02 0.09 0.05"/>
            </geometry>
            <material name="camera_material">
                <color rgba="0.015996293361446288 0.22696587349938613 0.07036009568874305 1"/>
            </material>
        </visual>
        <collision>
            <origin xyz="0 0 0" rpy="0 0 0"/>
            <geometry>
                <box size="0.02 0.09 0.05"/>
            </geometry>
        </collision>
        <inertial>
            <origin xyz="0 0 0" rpy="0 0 0"/>
            <mass value="1"/>
            <inertia ixx="0.16666666666666666" ixy="0" ixz="0" iyy="0.16666666666666666" iyz="0" izz="0.16666666666666666"/>
        </inertial>
    </link>

    <!-- Camera Joint -->
    <joint name="camera_joint" type="fixed">
        <parent link="base_link"/>
        <child link="camera_link"/>
        <origin xyz="0.23 0 0.0" rpy="0 0 0"/>
        <axis xyz="0 1 0"/>

        <limit lower="-1.14" upper="1.14" velocity="3.14" effort="10.0"/>
    </joint>

    <!-- IMU Link -->
    <link name="imu_link">
        <visual>
            <origin xyz="0 0 0" rpy="0 0 0"/>
            <geometry>
                <box size="0.02 0.02 0.02"/>
            </geometry>
            <material name="camera_material">
                <color rgba="0.015996293361446288 0.22696587349938613 0.07036009568874305 1"/>
            </material>
        </visual>
        <collision>
            <origin xyz="0 0 0" rpy="0 0 0"/>
            <geometry>
                <box size="0.02 0.02 0.02"/>
            </geometry>
        </collision>
        <inertial>
            <origin xyz="0 0 0" rpy="0 0 0"/>
            <mass value="1"/>
            <inertia ixx="0.16666666666666666" ixy="0" ixz="0" iyy="0.16666666666666666" iyz="0" izz="0.16666666666666666"/>
        </inertial>
    </link>

    <!-- IMU Joint -->
    <joint name="imu_joint" type="fixed">
        <parent link="base_link"/>
        <child link="imu_link"/>
        <origin xyz="-0.1 0 0.05" rpy="0 0 0"/> 
    </joint>

</robot>