<robot name="dummybot">

    <link name="base_link">
        <inertial>
            <origin xyz="0.0 0.0 0.0" rpy="0.0 0.0 0.0"/>
            <mass value="1.0"/>
            <inertia ixx="1.0" ixy="0.0" ixz="0.0" iyy="1.0" iyz="0.0" izz="1.0"/>
        </inertial>
        <visual name="base_link_visual">
            <origin xyz="0.0 0.0 0.0" rpy="0.0 0.0 0.0"/>
            <geometry>
                <box size="0.4 0.2 0.1"/>
            </geometry>
            <material name="">
                <color rgba="0.1 0.0 0.5 1.0"/>
                <texture filename=""/>
            </material>
        </visual>
        <collision>
            <origin xyz="0.0 0.0 0.0" rpy="0.0 0.0 0.0"/>
            <geometry>
                <box size="0.4 0.2 0.1"/>
            </geometry>
        </collision>
    </link>

    <link name="left_wheel">
        <inertial>
            <origin xyz="0.0 0.0 0.0" rpy="0.0 0.0 0.0"/>
            <mass value="1.0"/>
            <inertia ixx="1.0" ixy="0.0" ixz="0.0" iyy="1.0" iyz="0.0" izz="1.0"/>
        </inertial>
        <visual name="left_wheel_visual">
            <origin xyz="0.0 0.0 0.0" rpy="0.0 0.0 0.0"/>
            <geometry>
                <cylinder radius="0.1" length="0.05"/>
            </geometry>
            <material name="">
                <color rgba="0.5 0.2 0.1 1.0"/>
                <texture filename=""/>
            </material>
        </visual>
        <collision name='left_wheel_collision'>
            <origin xyz="0.0 0.0 0.0" rpy="0.0 0.0 0.0"/>
            <geometry>
                <cylinder radius="0.1" length="0.05"/>
            </geometry>
        </collision>
    </link>

    <link name="right_wheel">
        <inertial>
            <origin xyz="0.0 0.0 0.0" rpy="0.0 0.0 0.0"/>
            <mass value="1.0"/>
            <inertia ixx="1.0" ixy="0.0" ixz="0.0" iyy="1.0" iyz="0.0" izz="1.0"/>
        </inertial>
        <visual name="right_wheel_visual">
            <origin xyz="0.0 0.0 0.0" rpy="0.0 0.0 0.0"/>
            <geometry>
                <cylinder radius="0.1" length="0.05"/>
            </geometry>
            <material name="">
                <color rgba="0.5 0.2 0.1 1.0"/>
                <texture filename=""/>
            </material>
        </visual>
        <collision name='right_wheel_collision'>
            <origin xyz="0.0 0.0 0.0" rpy="0.0 0.0 0.0"/>
            <geometry>
                <cylinder radius="0.1" length="0.05"/>
            </geometry>
        </collision>
    </link>

    <joint name="wheel_left_joint" type="continuous">
        <origin xyz="0.0 0.15 0.0" rpy="0.0 1.5705 1.5705"/>
        <parent link="base_link"/>
        <child link="left_wheel"/>
        <axis xyz="0.0 0.0 1.0"/>

    </joint>


    <joint name="wheel_right_joint" type="continuous">
        <origin xyz="0.0 -0.15 0.0" rpy="0.0 1.5705 1.5705"/>
        <parent link="base_link"/>
        <child link="right_wheel"/>
        <axis xyz="0.0 0.0 1.0"/>

    </joint>


    <link name="front_caster">
        <inertial>
            <origin xyz="0.0 0.0 0.0" rpy="0.0 0.0 0.0"/>
            <mass value="1.0"/>
            <inertia ixx="1.0" ixy="0.0" ixz="0.0" iyy="1.0" iyz="0.0" izz="1.0"/>
        </inertial>
        <visual name="front_caster_visual">
            <origin xyz="0.0 0.0 0.0" rpy="0.0 0.0 0.0"/>
            <geometry>
                <sphere radius="0.0499"/>
            </geometry>
            <material name="">
                <color rgba="0.1 0.1 0.1 1.0"/>
                <texture filename=""/>
            </material>
        </visual>
        <collision>
            <origin xyz="0.0 0.0 0.0" rpy="0.0 0.0 0.0"/>
            <geometry>
                <sphere radius="0.0499"/>
            </geometry>
        </collision>
    </link>

    <joint name="front_caster_joint" type="fixed">
        <origin xyz="0.15 0.0 -0.05" rpy="0.0 0.0 0.0"/>
        <parent link="base_link"/>
        <child link="front_caster"/>
        <axis xyz="0.0 0.0 0.0"/>
    </joint>

 <link name="back_caster">
        <inertial>
            <origin xyz="0.0 0.0 0.0" rpy="0.0 0.0 0.0"/>
            <mass value="1.0"/>
            <inertia ixx="1.0" ixy="0.0" ixz="0.0" iyy="1.0" iyz="0.0" izz="1.0"/>
        </inertial>
        <visual name="back_caster_visual">
            <origin xyz="0.0 0.0 0.0" rpy="0.0 0.0 0.0"/>
            <geometry>
                <sphere radius="0.0499"/>
            </geometry>
            <material name="">
                <color rgba="0.1 0.1 0.1 1.0"/>
                <texture filename=""/>
            </material>
        </visual>
        <collision>
            <origin xyz="0.0 0.0 0.0" rpy="0.0 0.0 0.0"/>
            <geometry>
                <sphere radius="0.0499"/>
            </geometry>
        </collision>
    </link>

    <joint name="back_caster_joint" type="fixed">
        <origin xyz="-0.15 0.0 -0.05" rpy="0.0 0.0 0.0"/>
        <parent link="base_link"/>
        <child link="back_caster"/>
        <axis xyz="0.0 0.0 0.0"/>
    </joint>


</robot>